Workbook
Name WpnRow: 'Stat Calc'!#REF!

Sheet Stat Calc
D1: Formeln
B2: Starting Class | D2: Max HP | E2: 100 + (6*VIT)+(2,5*STR)+(2,3*DEX)+(2,2*INT)+(2,2*Faith)
B3: Warrior | D3: Max MP | E3: 100 + (6*INT)+(2,5*Faith)+(2,3*VIT)+(2,2*DEX)+(2,2*STR)
B4: Starting Stats: (10 Start Points) | D4: Physical Damage
B5: Vitality | C5: 3 | D5: Magical Damage
B6: Strength | C6: 3 | D6: Critical Chance
B7: Dexterity | C7: 2 | D7: Hit Chance
B8: Faith | C8: 1
B9: Intelligence | C9: 1

Sheet Melee Weapons
A1: Daggers
A2: Weapon Name | B2: Requirements | C2: Scaling | D2: Optimal Stats | E2: 1h/2h | F2: AR at minimum | G2: AR at optimal | H2: AR at max | I2: Weight | J2: spEffects | K2: Notes | L2: Speed
A3: Dagger +15 | B3: 5/8/-/- | C3: E/A/-/- | D3: 40 dex | E3: 1h | F3: 148 | G3: 262 | H3: 283 | I3: 0.5 | K3: Crit 131 | L3: Fast
A4: Crysal Dagger +5 | F4: 160 | G4: 283 | H4: 305
A5: Parrying Dagger +15 | B5: 5/14/-/- | C5: E/A/-/- | D5: 40 dex | E5: 1h | F5: 162 | G5: 252 | H5: 273 | I5: 0.5 | K5: Crit 131 | L5: Fast
A6: Crystal Parrying Dagger +5 | F6: 175 | G6: 273 | H6: 294
A7: Bandit's Knife +15 | B7: 6/12/-/- | C7: E/A/-/- | D7: 40 dex | E7: 1h | F7: 158 | G7: 262 | H7: 283 | I7: 1 | J7: 6400 | K7: Crit 147; Bleed 300 | L7: Slow
A8: Crystal Knife +5 | F8: 170 | G8: 283 | H8: 305
A9: Ghost Blade +5 | B9: 5/-/-/- | C9: E/-/-/- | D9: 40 str | E9: 1h | F9: 165 | G9: 181 | H9: 183 | I9: 0.5 | K9: Cirt 127; Hits ghosts | L9: Fast
A10: Dark Silver Tracer +5 | B10: 6/25/-/- | C10: E/S/-/- | D10: 40 dex | E10: 1h | F10: 196 | G10: 251 | H10: 263 | I10: 1 | K10: Crit 160; R2s cause Toxic | L10: Slow
A11: Priscilla's Dagger +5 | B11: 6/20/-/- | C11: -/S/-/- | D11: 40 dex | E11: 1h | F11: 190 | G11: 269 | H11: 271 | I11: 1 | J11: 6410 | K11: Bleed 500; Occult 110 | L11: Slow
A12: Straight Swords
A13: Weapon Name | B13: Requirements | C13: Scaling | D13: Optimal Stats | E13: 1h/2h | F13: AR at minimum | G13: AR at optimal | H13: AR at max | I13: Weight | J13: spEffects | K13: Notes | L13: Speed
A14: Shortsword +15 | B14: 8/10/-/- | C14: C/C/-/- | D14: 40/40 | E14: 1h | F14: 210 | G14: 397 | H14: 407 | I14: 2 | L14: Fast
A15: Crystal Shortsword +5 | F15: 227 | G15: 429 | H15: 439
A16: Longsword +15 | B16: 10/10/-/- | C16: C/C/-/- | D16: 40/40 | E16: 1h | F16: 216 | G16: 408 | H16: 417 | I16: 3 | L16: Fast
A17: Crystal Longsword +5 | F17: 233 | G17: 440 | H17: 451
A18: Broadsword +15 | B18: 10/10/-/- | C18: C/C/-/- | D18: 40/40 | E18: 1h | F18: 221 | G18: 418 | H18: 428 | I18: 3 | L18: Fast
A19: Crystal Broadsword +5 | F19: 239 | G19: 451 | H19: 462
A20: Balder Side Sword +15 | B20: 10/14/-/- | C20: E/A/-/- | D20: 40 dex | E20: 1h | F20: 240 | G20: 374 | H20: 404 | I20: 3 | L20: Fast
A21: Crystal Balder Side Sword +5 | F21: 259 | G21: 404 | H21: 436
A22: Sunlight Straight Sword +15 | B22: 12/12/-/- | C22: C/C/-/- | D22: 40/40 | E22: 1h | F22: 235 | G22: 418 | H22: 428 | I22: 4 | L22: Slow
A23: Crys. Sunlight Str. Sword +5 | F23: 253 | G23: 451 | H23: 462
A24: Darksword +15 | B24: 16/16/-/- | C24: C/C/-/- | D24: 40/40 | E24: 1h | F24: 270 | G24: 418 | H24: 428 | I24: 6 | L24: Slow
A25: Crystal Darksword +5 | F25: 291 | G25: 451 | H25: 462
A26: Barbed Straight Sword +15 | B26: 10/10/-/- | C26: D/C/-/- | D26: 40/40 | E26: 1h | F26: 214 | G26: 379 | H26: 387 | I26: 3 | J26: 6401 | K26: Bleed 300 | L26: Fast
A27: Crys. Barbed Str. Sword +5 | F27: 231 | G27: 409 | H27: 418
A28: Crystal Straight Sword | B28: 16/10/-/- | C28: C/C/-/- | D28: 40/40 | E28: 1h | F28: 176 | G28: 290 | H28: 296 | I28: 6 | L28: Slow
A29: Silv. Knight Str. Sword +5 | B29: 16/22/-/- | C29: E/C/-/- | D29: 40 dex | E29: 1h | F29: 328 | G29: 383 | H29: 399 | I29: 6 | L29: Slow
A30: Astora's Straight Sword +5 | B30: 10/10/-/14 | C30: C/C/-/C | D30: 40/40/-/40 | E30: 1h | F30: 270 (139+131) | G30: 396 (224+172) | H30: 402 (229+173) | I30: 3 | K30: Holy 120 | L30: Fast
A31: Drake Sword +5 | B31: 16/10/-/- | C31: -/-/-/- | D31: 16/10/-/- | E31: 1h | F31: 300 | I31: 6 | J31: 6810 | L31: Slow
A32: Broken Straight Sword +15 | B32: 8/8/-/- | C32: D/C/-/- | D32: 40/40 | E32: 1h | F32: 107 | G32: 189 | H32: 193 | I32: 2 | L32: Fast
A33: Crys. Broken Str. Sword +5 | F33: 116 | G33: 204 | H33: 209
A34: Straight Sword Hilt +15 | B34: 6/6/-/- | C34: E/E/-/- | D34: 40/40 | E34: 1h | F34: 50 | G34: 57 | H34: 58 | I34: 1 | L34: Fast
A35: Crystal Str. Sword Hilt +5 | F35: 54 | G35: 62 | H35: 62
A36: Greatswords
A37: Weapon Name | B37: Requirements | C37: Scaling | D37: Optimal Stats | E37: 1h/2h | F37: AR at minimum | G37: AR at optimal | H37: AR at max | I37: Weight | J37: spEffects | K37: Notes | L37: Speed
A38: Basard Sword +15 | B38: 16/10/-/- | C38: C/C/-/- | D38: 27/40 | E38: 2h | F38: 349 | G38: 535 | H38: 561 | I38: 6 | L38: Fast
A39: Bastard Sword +5 | F39: 377 | G39: 578 | H39: 606
A40: Claymore +15 | B40: 16/10/-/- | C40: C/C/-/- | D40: 27/40 | E40: 2h | F40: 342 | G40: 525 | H40: 551 | I40: 6 | L40: Fast
...

Sheet Helms
A1: ID | B1: Name | C1: Poise | D1: physDef | E1: magDef | F1: fireDef | G1: litngDef | H1: slashDef | I1: blowDef | J1: thrustDef | K1: poisonRes | L1: toxicRes | M1: bleedRes | N1: curseRes | O1: Weight | P1: Durability | Q1: RegPenalty | S1: Poise/Weight | T1: physDef/Weight | U1: magDef/Weight | V1: fireDef/Weight | W1: lingDef/Weight | X1: slash/Weight | Y1: blow/Weight | Z1: thrust/Weight | AA1: poison/Weight | AB1: bleed/Weight
A2: =UpgradedProtectorStats!A2+5 -> 10010 | B2: Catarina Helm +5 | C2: =UpgradedProtectorStats!C2 -> 8 | D2: =UpgradedProtectorStats!D2 -> 34.1 | E2: =UpgradedProtectorStats!E2 -> 18.6 | F2: =UpgradedProtectorStats!F2 -> 20.15 | G2: =UpgradedProtectorStats!G2 -> 10.85 | H2: =UpgradedProtectorStats!D2*(1+(UpgradedProtectorStats!H2/100)) -> 39.215 | I2: =UpgradedProtectorStats!D2*(1+(UpgradedProtectorStats!I2/100)) -> 33.759 | J2: =UpgradedProtectorStats!D2*(1+(UpgradedProtectorStats!J2/100)) -> 34.1 | K2: =UpgradedProtectorStats!K2 -> 11.43 | L2: =UpgradedProtectorStats!L2 -> 11.43 | M2: =UpgradedProtectorStats!M2 -> 16.51 | N2: =UpgradedProtectorStats!N2 -> 0 | O2: =UpgradedProtectorStats!O2 -> 4.5 | P2: =UpgradedProtectorStats!P2 -> 400 | Q2: =UpgradedProtectorStats!Q2 -> -1 | S2: =C2/O2 -> 1.7777778 | T2: =D2/O2 -> 7.5777778 | U2: =E2/O2 -> 4.1333333 | V2: =F2/O2 -> 4.4777778 | W2: =G2/O2 -> 2.4111111 | X2: =H2/O2 -> 8.7144444 | Y2: =I2/O2 -> 7.502 | Z2: =J2/O2 -> 7.5777778 | AA2: =K2/O2 -> 2.54 | AB2: =M2/O2 -> 3.6688889
A3: =UpgradedProtectorStats!A6+5 -> 20010 | B3: Paladin Helm +5 | C3: =UpgradedProtectorStats!C6 -> 8 | D3: =UpgradedProtectorStats!D6 -> 34.1 | E3: =UpgradedProtectorStats!E6 -> 18.6 | F3: =UpgradedProtectorStats!F6 -> 20.15 | G3: =UpgradedProtectorStats!G6 -> 10.85 | H3: =UpgradedProtectorStats!D6*(1+(UpgradedProtectorStats!H6/100)) -> 39.215 | I3: =UpgradedProtectorStats!D6*(1+(UpgradedProtectorStats!I6/100)) -> 32.395 | J3: =UpgradedProtectorStats!D6*(1+(UpgradedProtectorStats!J6/100)) -> 34.1 | K3: =UpgradedProtectorStats!K6 -> 11.43 | L3: =UpgradedProtectorStats!L6 -> 11.43 | M3: =UpgradedProtectorStats!M6 -> 16.51 | N3: =UpgradedProtectorStats!N6 -> 27.94 | O3: =UpgradedProtectorStats!O6 -> 5 | P3: =UpgradedProtectorStats!P6 -> 500 | Q3: =UpgradedProtectorStats!Q6 -> -1 | S3: =C3/O3 -> 1.6 | T3: =D3/O3 -> 6.82 | U3: =E3/O3 -> 3.72 | V3: =F3/O3 -> 4.03 | W3: =G3/O3 -> 2.17 | X3: =H3/O3 -> 7.843 | Y3: =I3/O3 -> 6.479 | Z3: =J3/O3 -> 6.82 | AA3: =K3/O3 -> 2.286 | AB3: =M3/O3 -> 3.302
A4: =UpgradedProtectorStats!A10+5 -> 40010 | B4: Dark Mask +5 | C4: =UpgradedProtectorStats!C10 -> 6 | D4: =UpgradedProtectorStats!D10 -> 27.9 | E4: =UpgradedProtectorStats!E10 -> 18.6 | F4: =UpgradedProtectorStats!F10 -> 18.6 | G4: =UpgradedProtectorStats!G10 -> 15.5 | H4: =UpgradedProtectorStats!D10*(1+(UpgradedProtectorStats!H10/100)) -> 30.69 | I4: =UpgradedProtectorStats!D10*(1+(UpgradedProtectorStats!I10/100)) -> 27.9 | J4: =UpgradedProtectorStats!D10*(1+(UpgradedProtectorStats!J10/100)) -> 26.226 | K4: =UpgradedProtectorStats!K10 -> 10.16 | L4: =UpgradedProtectorStats!L10 -> 10.16 | M4: =UpgradedProtectorStats!M10 -> 15.24 | N4: =UpgradedProtectorStats!N10 -> 0 | O4: =UpgradedProtectorStats!O10 -> 3.8 | P4: =UpgradedProtectorStats!P10 -> 300 | Q4: =UpgradedProtectorStats!Q10 -> 0 | S4: =C4/O4 -> 1.5789474 | T4: =D4/O4 -> 7.3421053 | U4: =E4/O4 -> 4.8947368 | V4: =F4/O4 -> 4.8947368 | W4: =G4/O4 -> 4.0789474 | X4: =H4/O4 -> 8.0763158 | Y4: =I4/O4 -> 7.3421053 | Z4: =J4/O4 -> 6.9015789 | AA4: =K4/O4 -> 2.6736842 | AB4: =M4/O4 -> 4.0105263
A5: =UpgradedProtectorStats!A14+10 -> 50020 | B5: Brigand Hood +10 | C5: =UpgradedProtectorStats!C14 -> 0 | D5: =UpgradedProtectorStats!D14 -> 21.78 | E5: =UpgradedProtectorStats!E14 -> 19.36 | F5: =UpgradedProtectorStats!F14 -> 12.1 | G5: =UpgradedProtectorStats!G14 -> 14.52 | H5: =UpgradedProtectorStats!D14*(1+(UpgradedProtectorStats!H14/100)) -> 21.78 | I5: =UpgradedProtectorStats!D14*(1+(UpgradedProtectorStats!I14/100)) -> 23.958 | J5: =UpgradedProtectorStats!D14*(1+(UpgradedProtectorStats!J14/100)) -> 19.602 | K5: =UpgradedProtectorStats!K14 -> 11.2 | L5: =UpgradedProtectorStats!L14 -> 11.2 | M5: =UpgradedProtectorStats!M14 -> 11.2 | N5: =UpgradedProtectorStats!N14 -> 0 | O5: =UpgradedProtectorStats!O14 -> 1.2 | P5: =UpgradedProtectorStats!P14 -> 200 | Q5: =UpgradedProtectorStats!Q14 -> 0 | S5: =C5/O5 -> 0 | T5: =D5/O5 -> 18.15 | U5: =E5/O5 -> 16.133333 | V5: =F5/O5 -> 10.083333 | W5: =G5/O5 -> 12.1 | X5: =H5/O5 -> 18.15 | Y5: =I5/O5 -> 19.965 | Z5: =J5/O5 -> 16.335 | AA5: =K5/O5 -> 9.3333333 | AB5: =M5/O5 -> 9.3333333
A6: =UpgradedProtectorStats!A18+5 -> 60010 | B6: Shadow Mask +5 | C6: =UpgradedProtectorStats!C18 -> 0 | D6: =UpgradedProtectorStats!D18 -> 21.78 | E6: =UpgradedProtectorStats!E18 -> 12.1 | F6: =UpgradedProtectorStats!F18 -> 14.52 | G6: =UpgradedProtectorStats!G18 -> 14.52 | H6: =UpgradedProtectorStats!D18*(1+(UpgradedProtectorStats!H18/100)) -> 21.78 | I6: =UpgradedProtectorStats!D18*(1+(UpgradedProtectorStats!I18/100)) -> 23.958 | J6: =UpgradedProtectorStats!D18*(1+(UpgradedProtectorStats!J18/100)) -> 21.78 | K6: =UpgradedProtectorStats!K18 -> 25.2 | L6: =UpgradedProtectorStats!L18 -> 25.2 | M6: =UpgradedProtectorStats!M18 -> 21 | N6: =UpgradedProtectorStats!N18 -> 0 | O6: =UpgradedProtectorStats!O18 -> 0.9 | P6: =UpgradedProtectorStats!P18 -> 200 | Q6: =UpgradedProtectorStats!Q18 -> 0 | S6: =C6/O6 -> 0 | T6: =D6/O6 -> 24.2 | U6: =E6/O6 -> 13.444444 | V6: =F6/O6 -> 16.133333 | W6: =G6/O6 -> 16.133333 | X6: =H6/O6 -> 24.2 | Y6: =I6/O6 -> 26.62 | Z6: =J6/O6 -> 24.2 | AA6: =K6/O6 -> 28 | AB6: =M6/O6 -> 23.333333
A7: =UpgradedProtectorStats!A22+5 -> 70010 | B7: Black Iron Helm +5 | C7: =UpgradedProtectorStats!C22 -> 12 | D7: =UpgradedProtectorStats!D22 -> 65.34 | E7: =UpgradedProtectorStats!E22 -> 26.62 | F7: =UpgradedProtectorStats!F22 -> 45.98 | G7: =UpgradedProtectorStats!G22 -> 19.36 | H7: =UpgradedProtectorStats!D22*(1+(UpgradedProtectorStats!H22/100)) -> 75.141 | I7: =UpgradedProtectorStats!D22*(1+(UpgradedProtectorStats!I22/100)) -> 62.073 | J7: =UpgradedProtectorStats!D22*(1+(UpgradedProtectorStats!J22/100)) -> 65.34 | K7: =UpgradedProtectorStats!K22 -> 14 | L7: =UpgradedProtectorStats!L22 -> 14 | M7: =UpgradedProtectorStats!M22 -> 23.8 | N7: =UpgradedProtectorStats!N22 -> 7 | O7: =UpgradedProtectorStats!O22 -> 6 | P7: =UpgradedProtectorStats!P22 -> 600 | Q7: =UpgradedProtectorStats!Q22 -> -1 | S7: =C7/O7 -> 2 | T7: =D7/O7 -> 10.89 | U7: =E7/O7 -> 4.4366667 | V7: =F7/O7 -> 7.6633333 | W7: =G7/O7 -> 3.2266667 | X7: =H7/O7 -> 12.5235 | Y7: =I7/O7 -> 10.3455 | Z7: =J7/O7 -> 10.89 | AA7: =K7/O7 -> 2.3333333 | AB7: =M7/O7 -> 3.9666667
A8: =UpgradedProtectorStats!A26 -> 80000 | B8: Smough's Helm | C8: =UpgradedProtectorStats!C26 -> 14 | D8: =UpgradedProtectorStats!D26 -> 40 | E8: =UpgradedProtectorStats!E26 -> 19 | F8: =UpgradedProtectorStats!F26 -> 26 | G8: =UpgradedProtectorStats!G26 -> 21 | H8: =UpgradedProtectorStats!D26*(1+(UpgradedProtectorStats!H26/100)) -> 46 | I8: =UpgradedProtectorStats!D26*(1+(UpgradedProtectorStats!I26/100)) -> 34.8 | J8: =UpgradedProtectorStats!D26*(1+(UpgradedProtectorStats!J26/100)) -> 40 | K8: =UpgradedProtectorStats!K26 -> 12 | L8: =UpgradedProtectorStats!L26 -> 12 | M8: =UpgradedProtectorStats!M26 -> 21 | N8: =UpgradedProtectorStats!N26 -> 5 | O8: =UpgradedProtectorStats!O26 -> 6.8 | P8: =UpgradedProtectorStats!P26 -> 700 | Q8: =UpgradedProtectorStats!Q26 -> -1 | S8: =C8/O8 -> 2.0588235 | T8: =D8/O8 -> 5.8823529 | U8: =E8/O8 -> 2.7941176 | V8: =F8/O8 -> 3.8235294 | W8: =G8/O8 -> 3.0882353 | X8: =H8/O8 -> 6.7647059 | Y8: =I8/O8 -> 5.1176471 | Z8: =J8/O8 -> 5.8823529 | AA8: =K8/O8 -> 1.7647059 | AB8: =M8/O8 -> 3.0882353
A9: =UpgradedProtectorStats!A30 -> 90000 | B9: Six-Eyed Helm of the Channelers | C9: =UpgradedProtectorStats!C30 -> 5 | D9: =UpgradedProtectorStats!D30 -> 20 | E9: =UpgradedProtectorStats!E30 -> 18 | F9: =UpgradedProtectorStats!F30 -> 17 | G9: =UpgradedProtectorStats!G30 -> 13 | H9: =UpgradedProtectorStats!D30*(1+(UpgradedProtectorStats!H30/100)) -> 22.8 | I9: =UpgradedProtectorStats!D30*(1+(UpgradedProtectorStats!I30/100)) -> 19.2 | J9: =UpgradedProtectorStats!D30*(1+(UpgradedProtectorStats!J30/100)) -> 20 | K9: =UpgradedProtectorStats!K30 -> 13 | L9: =UpgradedProtectorStats!L30 -> 13 | M9: =UpgradedProtectorStats!M30 -> 15 | N9: =UpgradedProtectorStats!N30 -> 0 | O9: =UpgradedProtectorStats!O30 -> 3.9 | P9: =UpgradedProtectorStats!P30 -> 300 | Q9: =UpgradedProtectorStats!Q30 -> 0 | S9: =C9/O9 -> 1.2820513 | T9: =D9/O9 -> 5.1282051 | U9: =E9/O9 -> 4.6153846 | V9: =F9/O9 -> 4.3589744 | W9: =G9/O9 -> 3.3333333 | X9: =H9/O9 -> 5.8461538 | Y9: =I9/O9 -> 4.9230769 | Z9: =J9/O9 -> 5.1282051 | AA9: =K9/O9 -> 3.3333333 | AB9: =M9/O9 -> 3.8461538
A10: =UpgradedProtectorStats!A34+5 -> 100010 | B10: Helm of Favor +5 | C10: =UpgradedProtectorStats!C34 -> 8 | D10: =UpgradedProtectorStats!D34 -> 27.9 | E10: =UpgradedProtectorStats!E34 -> 15.5 | F10: =UpgradedProtectorStats!F34 -> 17.05 | G10: =UpgradedProtectorStats!G34 -> 10.85 | H10: =UpgradedProtectorStats!D34*(1+(UpgradedProtectorStats!H34/100)) -> 32.364 | I10: =UpgradedProtectorStats!D34*(1+(UpgradedProtectorStats!I34/100)) -> 26.505 | J10: =UpgradedProtectorStats!D34*(1+(UpgradedProtectorStats!J34/100)) -> 27.9 | K10: =UpgradedProtectorStats!K34 -> 10.16 | L10: =UpgradedProtectorStats!L34 -> 10.16 | M10: =UpgradedProtectorStats!M34 -> 13.97 | N10: =UpgradedProtectorStats!N34 -> 10.16 | O10: =UpgradedProtectorStats!O34 -> 4.5 | P10: =UpgradedProtectorStats!P34 -> 500 | Q10: =UpgradedProtectorStats!Q34 -> 0 | S10: =C10/O10 -> 1.7777778 | T10: =D10/O10 -> 6.2 | U10: =E10/O10 -> 3.4444444 | V10: =F10/O10 -> 3.7888889 | W10: =G10/O10 -> 2.4111111 | X10: =H10/O10 -> 7.192 | Y10: =I10/O10 -> 5.89 | Z10: =J10/O10 -> 6.2 | AA10: =K10/O10 -> 2.2577778 | AB10: =M10/O10 -> 3.1044444
A11: =UpgradedProtectorStats!A38 -> 110000 | B11: Helm of the Wise | C11: =UpgradedProtectorStats!C38 -> 8 | D11: =UpgradedProtectorStats!D38 -> 18 | E11: =UpgradedProtectorStats!E38 -> 12 | F11: =UpgradedProtectorStats!F38 -> 13 | G11: =UpgradedProtectorStats!G38 -> 10 | H11: =UpgradedProtectorStats!D38*(1+(UpgradedProtectorStats!H38/100)) -> 20.7 | I11: =UpgradedProtectorStats!D38*(1+(UpgradedProtectorStats!I38/100)) -> 17.1 | J11: =UpgradedProtectorStats!D38*(1+(UpgradedProtectorStats!J38/100)) -> 18 | K11: =UpgradedProtectorStats!K38 -> 7 | L11: =UpgradedProtectorStats!L38 -> 7 | M11: =UpgradedProtectorStats!M38 -> 11 | N11: =UpgradedProtectorStats!N38 -> 18 | O11: =UpgradedProtectorStats!O38 -> 5.1 | P11: =UpgradedProtectorStats!P38 -> 500 | Q11: =UpgradedProtectorStats!Q38 -> 0 | S11: =C11/O11 -> 1.5686275 | T11: =D11/O11 -> 3.5294118 | U11: =E11/O11 -> 2.3529412 | V11: =F11/O11 -> 2.5490196 | W11: =G11/O11 -> 1.9607843 | X11: =H11/O11 -> 4.0588235 | Y11: =I11/O11 -> 3.3529412 | Z11: =J11/O11 -> 3.5294118 | AA11: =K11/O11 -> 1.372549 | AB11: =M11/O11 -> 2.1568627
A12: =UpgradedProtectorStats!A42 -> 120000 | B12: Stone Helm | C12: =UpgradedProtectorStats!C42 -> 15 | D12: =UpgradedProtectorStats!D42 -> 35 | E12: =UpgradedProtectorStats!E42 -> 17 | F12: =UpgradedProtectorStats!F42 -> 21 | G12: =UpgradedProtectorStats!G42 -> 21 | H12: =UpgradedProtectorStats!D42*(1+(UpgradedProtectorStats!H42/100)) -> 40.25 | I12: =UpgradedProtectorStats!D42*(1+(UpgradedProtectorStats!I42/100)) -> 32.9 | J12: =UpgradedProtectorStats!D42*(1+(UpgradedProtectorStats!J42/100)) -> 35 | K12: =UpgradedProtectorStats!K42 -> 6 | L12: =UpgradedProtectorStats!L42 -> 6 | M12: =UpgradedProtectorStats!M42 -> 17 | N12: =UpgradedProtectorStats!N42 -> 0 | O12: =UpgradedProtectorStats!O42 -> 6.8 | P12: =UpgradedProtectorStats!P42 -> 800 | Q12: =UpgradedProtectorStats!Q42 -> -1 | S12: =C12/O12 -> 2.2058824 | T12: =D12/O12 -> 5.1470588 | U12: =E12/O12 -> 2.5 | V12: =F12/O12 -> 3.0882353 | W12: =G12/O12 -> 3.0882353 | X12: =H12/O12 -> 5.9191176 | Y12: =I12/O12 -> 4.8382353 | Z12: =J12/O12 -> 5.1470588 | AA12: =K12/O12 -> 0.88235294 | AB12: =M12/O12 -> 2.5
A13: =UpgradedProtectorStats!A46 -> 130000 | B13: Crystalline Helm | C13: =UpgradedProtectorStats!C46 -> 6 | D13: =UpgradedProtectorStats!D46 -> 25 | E13: =UpgradedProtectorStats!E46 -> 8 | F13: =UpgradedProtectorStats!F46 -> 6 | G13: =UpgradedProtectorStats!G46 -> 2 | H13: =UpgradedProtectorStats!D46*(1+(UpgradedProtectorStats!H46/100)) -> 28.75 | I13: =UpgradedProtectorStats!D46*(1+(UpgradedProtectorStats!I46/100)) -> 21.25 | J13: =UpgradedProtectorStats!D46*(1+(UpgradedProtectorStats!J46/100)) -> 25 | K13: =UpgradedProtectorStats!K46 -> 0 | L13: =UpgradedProtectorStats!L46 -> 0 | M13: =UpgradedProtectorStats!M46 -> 6 | N13: =UpgradedProtectorStats!N46 -> 0 | O13: =UpgradedProtectorStats!O46 -> 4.2 | P13: =UpgradedProtectorStats!P46 -> 150 | Q13: =UpgradedProtectorStats!Q46 -> 0 | S13: =C13/O13 -> 1.4285714 | T13: =D13/O13 -> 5.952381 | U13: =E13/O13 -> 1.9047619 | V13: =F13/O13 -> 1.4285714 | W13: =G13/O13 -> 0.47619048 | X13: =H13/O13 -> 6.8452381 | Y13: =I13/O13 -> 5.0595238 | Z13: =J13/O13 -> 5.952381 | AA13: =K13/O13 -> 0 | AB13: =M13/O13 -> 1.4285714
A14: =UpgradedProtectorStats!A50+5 -> 140010 | B14: Mask of the Sealer +5 | C14: =UpgradedProtectorStats!C50 -> 0 | D14: =UpgradedProtectorStats!D50 -> 18.6 | E14: =UpgradedProtectorStats!E50 -> 18.6 | F14: =UpgradedProtectorStats!F50 -> 10.85 | G14: =UpgradedProtectorStats!G50 -> 13.95 | H14: =UpgradedProtectorStats!D50*(1+(UpgradedProtectorStats!H50/100)) -> 18.6 | I14: =UpgradedProtectorStats!D50*(1+(UpgradedProtectorStats!I50/100)) -> 20.46 | J14: =UpgradedProtectorStats!D50*(1+(UpgradedProtectorStats!J50/100)) -> 18.6 | K14: =UpgradedProtectorStats!K50 -> 10.16 | L14: =UpgradedProtectorStats!L50 -> 10.16 | M14: =UpgradedProtectorStats!M50 -> 10.16 | N14: =UpgradedProtectorStats!N50 -> 10.16 | O14: =UpgradedProtectorStats!O50 -> 1.5 | P14: =UpgradedProtectorStats!P50 -> 400 | Q14: =UpgradedProtectorStats!Q50 -> 0 | S14: =C14/O14 -> 0 | T14: =D14/O14 -> 12.4 | U14: =E14/O14 -> 12.4 | V14: =F14/O14 -> 7.2333333 | W14: =G14/O14 -> 9.3 | X14: =H14/O14 -> 12.4 | Y14: =I14/O14 -> 13.64 | Z14: =J14/O14 -> 12.4 | AA14: =K14/O14 -> 6.7733333 | AB14: =M14/O14 -> 6.7733333
A15: =UpgradedProtectorStats!A54+5 -> 150010 | B15: Mask of Velka +5 | C15: =UpgradedProtectorStats!C54 -> 0 | D15: =UpgradedProtectorStats!D54 -> 18.6 | E15: =UpgradedProtectorStats!E54 -> 18.6 | F15: =UpgradedProtectorStats!F54 -> 15.5 | G15: =UpgradedProtectorStats!G54 -> 10.85 | H15: =UpgradedProtectorStats!D54*(1+(UpgradedProtectorStats!H54/100)) -> 18.6 | I15: =UpgradedProtectorStats!D54*(1+(UpgradedProtectorStats!I54/100)) -> 20.274 | J15: =UpgradedProtectorStats!D54*(1+(UpgradedProtectorStats!J54/100)) -> 18.6 | K15: =UpgradedProtectorStats!K54 -> 11.43 | L15: =UpgradedProtectorStats!L54 -> 11.43 | M15: =UpgradedProtectorStats!M54 -> 11.43 | N15: =UpgradedProtectorStats!N54 -> 25.4 | O15: =UpgradedProtectorStats!O54 -> 2.5 | P15: =UpgradedProtectorStats!P54 -> 400 | Q15: =UpgradedProtectorStats!Q54 -> 0 | S15: =C15/O15 -> 0 | T15: =D15/O15 -> 7.44 | U15: =E15/O15 -> 7.44 | V15: =F15/O15 -> 6.2 | W15: =G15/O15 -> 4.34 | X15: =H15/O15 -> 7.44 | Y15: =I15/O15 -> 8.1096 | Z15: =J15/O15 -> 7.44 | AA15: =K15/O15 -> 4.572 | AB15: =M15/O15 -> 4.572
A16: =UpgradedProtectorStats!A58+10 -> 160020 | B16: Iron Helm +10 | C16: =UpgradedProtectorStats!C58 -> 8 | D16: =UpgradedProtectorStats!D58 -> 33.88 | E16: =UpgradedProtectorStats!E58 -> 24.2 | F16: =UpgradedProtectorStats!F58 -> 24.2 | G16: =UpgradedProtectorStats!G58 -> 21.78 | H16: =UpgradedProtectorStats!D58*(1+(UpgradedProtectorStats!H58/100)) -> 33.88 | I16: =UpgradedProtectorStats!D58*(1+(UpgradedProtectorStats!I58/100)) -> 33.88 | J16: =UpgradedProtectorStats!D58*(1+(UpgradedProtectorStats!J58/100)) -> 33.2024 | K16: =UpgradedProtectorStats!K58 -> 11.2 | L16: =UpgradedProtectorStats!L58 -> 11.2 | M16: =UpgradedProtectorStats!M58 -> 16.8 | N16: =UpgradedProtectorStats!N58 -> 2.8 | O16: =UpgradedProtectorStats!O58 -> 4.5 | P16: =UpgradedProtectorStats!P58 -> 350 | Q16: =UpgradedProtectorStats!Q58 -> 0 | S16: =C16/O16 -> 1.7777778 | T16: =D16/O16 -> 7.5288889 | U16: =E16/O16 -> 5.3777778 | V16: =F16/O16 -> 5.3777778 | W16: =G16/O16 -> 4.84 | X16: =H16/O16 -> 7.5288889 | Y16: =I16/O16 -> 7.5288889 | Z16: =J16/O16 -> 7.3783111 | AA16: =K16/O16 -> 2.4888889 | AB16: =M16/O16 -> 3.7333333
A17: =UpgradedProtectorStats!A62+10 -> 170020 | B17: Chain Helm +10 | C17: =UpgradedProtectorStats!C62 -> 5 | D17: =UpgradedProtectorStats!D62 -> 29.04 | E17: =UpgradedProtectorStats!E62 -> 24.2 | F17: =UpgradedProtectorStats!F62 -> 19.36 | G17: =UpgradedProtectorStats!G62 -> 7.26 | H17: =UpgradedProtectorStats!D62*(1+(UpgradedProtectorStats!H62/100)) -> 34.848 | I17: =UpgradedProtectorStats!D62*(1+(UpgradedProtectorStats!I62/100)) -> 29.04 | J17: =UpgradedProtectorStats!D62*(1+(UpgradedProtectorStats!J62/100)) -> 28.1688 | K17: =UpgradedProtectorStats!K62 -> 8.4 | L17: =UpgradedProtectorStats!L62 -> 8.4 | M17: =UpgradedProtectorStats!M62 -> 14 | N17: =UpgradedProtectorStats!N62 -> 0 | O17: =UpgradedProtectorStats!O62 -> 3 | P17: =UpgradedProtectorStats!P62 -> 300 | Q17: =UpgradedProtectorStats!Q62 -> 0 | S17: =C17/O17 -> 1.6666667 | T17: =D17/O17 -> 9.68 | U17: =E17/O17 -> 8.0666667 | V17: =F17/O17 -> 6.4533333 | W17: =G17/O17 -> 2.42 | X17: =H17/O17 -> 11.616 | Y17: =I17/O17 -> 9.68 | Z17: =J17/O17 -> 9.3896 | AA17: =K17/O17 -> 2.8 | AB17: =M17/O17 -> 4.6666667
A18: =UpgradedProtectorStats!A66+10 -> 180020 | B18: Cleric Helm +10 | C18: =UpgradedProtectorStats!C66 -> 8 | D18: =UpgradedProtectorStats!D66 -> 36.3 | E18: =UpgradedProtectorStats!E66 -> 21.78 | F18: =UpgradedProtectorStats!F66 -> 19.36 | G18: =UpgradedProtectorStats!G66 -> 14.52 | H18: =UpgradedProtectorStats!D66*(1+(UpgradedProtectorStats!H66/100)) -> 41.745 | I18: =UpgradedProtectorStats!D66*(1+(UpgradedProtectorStats!I66/100)) -> 36.3 | J18: =UpgradedProtectorStats!D66*(1+(UpgradedProtectorStats!J66/100)) -> 36.3 | K18: =UpgradedProtectorStats!K66 -> 8.4 | L18: =UpgradedProtectorStats!L66 -> 8.4 | M18: =UpgradedProtectorStats!M66 -> 12.6 | N18: =UpgradedProtectorStats!N66 -> 0 | O18: =UpgradedProtectorStats!O66 -> 4.8 | P18: =UpgradedProtectorStats!P66 -> 500 | Q18: =UpgradedProtectorStats!Q66 -> -1 | S18: =C18/O18 -> 1.6666667 | T18: =D18/O18 -> 7.5625 | U18: =E18/O18 -> 4.5375 | V18: =F18/O18 -> 4.0333333 | W18: =G18/O18 -> 3.025 | X18: =H18/O18 -> 8.696875 | Y18: =I18/O18 -> 7.5625 | Z18: =J18/O18 -> 7.5625 | AA18: =K18/O18 -> 1.75 | AB18: =M18/O18 -> 2.625
A19: =UpgradedProtectorStats!A70 -> 190000 | B19: Sunlight Maggot | C19: =UpgradedProtectorStats!C70 -> 0 | D19: =UpgradedProtectorStats!D70 -> 6 | E19: =UpgradedProtectorStats!E70 -> 5 | F19: =UpgradedProtectorStats!F70 -> 24 | G19: =UpgradedProtectorStats!G70 -> 13 | H19: =UpgradedProtectorStats!D70*(1+(UpgradedProtectorStats!H70/100)) -> 6 | I19: =UpgradedProtectorStats!D70*(1+(UpgradedProtectorStats!I70/100)) -> 6 | J19: =UpgradedProtectorStats!D70*(1+(UpgradedProtectorStats!J70/100)) -> 6 | K19: =UpgradedProtectorStats!K70 -> 0 | L19: =UpgradedProtectorStats!L70 -> 0 | M19: =UpgradedProtectorStats!M70 -> 0 | N19: =UpgradedProtectorStats!N70 -> 0 | O19: =UpgradedProtectorStats!O70 -> 1.4 | P19: =UpgradedProtectorStats!P70 -> 80 | Q19: =UpgradedProtectorStats!Q70 -> 0 | S19: =C19/O19 -> 0 | T19: =D19/O19 -> 4.2857143 | U19: =E19/O19 -> 3.5714286 | V19: =F19/O19 -> 17.142857 | W19: =G19/O19 -> 9.2857143 | X19: =H19/O19 -> 4.2857143 | Y19: =I19/O19 -> 4.2857143 | Z19: =J19/O19 -> 4.2857143 | AA19: =K19/O19 -> 0 | AB19: =M19/O19 -> 0
A20: =UpgradedProtectorStats!A71+5 -> 200010 | B20: Helm of Thorns +5 | C20: =UpgradedProtectorStats!C71 -> 6 | D20: =UpgradedProtectorStats!D71 -> 26.35 | E20: =UpgradedProtectorStats!E71 -> 15.5 | F20: =UpgradedProtectorStats!F71 -> 18.6 | G20: =UpgradedProtectorStats!G71 -> 12.4 | H20: =UpgradedProtectorStats!D71*(1+(UpgradedProtectorStats!H71/100)) -> 28.7215 | I20: =UpgradedProtectorStats!D71*(1+(UpgradedProtectorStats!I71/100)) -> 25.0325 | J20: =UpgradedProtectorStats!D71*(1+(UpgradedProtectorStats!J71/100)) -> 26.35 | K20: =UpgradedProtectorStats!K71 -> 8.89 | L20: =UpgradedProtectorStats!L71 -> 8.89 | M20: =UpgradedProtectorStats!M71 -> 12.7 | N20: =UpgradedProtectorStats!N71 -> 0 | O20: =UpgradedProtectorStats!O71 -> 4.1 | P20: =UpgradedProtectorStats!P71 -> 250 | Q20: =UpgradedProtectorStats!Q71 -> 0 | S20: =C20/O20 -> 1.4634146 | T20: =D20/O20 -> 6.4268293 | U20: =E20/O20 -> 3.7804878 | V20: =F20/O20 -> 4.5365854 | W20: =G20/O20 -> 3.0243902 | X20: =H20/O20 -> 7.0052439 | Y20: =I20/O20 -> 6.1054878 | Z20: =J20/O20 -> 6.4268293 | AA20: =K20/O20 -> 2.1682927 | AB20: =M20/O20 -> 3.097561
A21: =UpgradedProtectorStats!A75+10 -> 210020 | B21: Standard Helm +10 | C21: =UpgradedProtectorStats!C75 -> 5 | D21: =UpgradedProtectorStats!D75 -> 33.88 | E21: =UpgradedProtectorStats!E75 -> 19.36 | F21: =UpgradedProtectorStats!F75 -> 19.36 | G21: =UpgradedProtectorStats!G75 -> 7.26 | H21: =UpgradedProtectorStats!D75*(1+(UpgradedProtectorStats!H75/100)) -> 38.6232 | I21: =UpgradedProtectorStats!D75*(1+(UpgradedProtectorStats!I75/100)) -> 19.3116 | J21: =UpgradedProtectorStats!D75*(1+(UpgradedProtectorStats!J75/100)) -> 33.88 | K21: =UpgradedProtectorStats!K75 -> 11.2 | L21: =UpgradedProtectorStats!L75 -> 11.2 | M21: =UpgradedProtectorStats!M75 -> 12.6 | N21: =UpgradedProtectorStats!N75 -> 0 | O21: =UpgradedProtectorStats!O75 -> 3.5 | P21: =UpgradedProtectorStats!P75 -> 250 | Q21: =UpgradedProtectorStats!Q75 -> 0 | S21: =C21/O21 -> 1.4285714 | T21: =D21/O21 -> 9.68 | U21: =E21/O21 -> 5.5314286 | V21: =F21/O21 -> 5.5314286 | W21: =G21/O21 -> 2.0742857 | X21: =H21/O21 -> 11.0352 | Y21: =I21/O21 -> 5.5176 | Z21: =J21/O21 -> 9.68 | AA21: =K21/O21 -> 3.2 | AB21: =M21/O21 -> 3.6
A22: =UpgradedProtectorStats!A79+10 -> 220020 | B22: Sorcerer Hat +10 | C22: =UpgradedProtectorStats!C79 -> 0 | D22: =UpgradedProtectorStats!D79 -> 19.36 | E22: =UpgradedProtectorStats!E79 -> 24.2 | F22: =UpgradedProtectorStats!F79 -> 12.1 | G22: =UpgradedProtectorStats!G79 -> 14.52 | H22: =UpgradedProtectorStats!D79*(1+(UpgradedProtectorStats!H79/100)) -> 20.1344 | I22: =UpgradedProtectorStats!D79*(1+(UpgradedProtectorStats!I79/100)) -> 20.9088 | J22: =UpgradedProtectorStats!D79*(1+(UpgradedProtectorStats!J79/100)) -> 19.36 | K22: =UpgradedProtectorStats!K79 -> 7 | L22: =UpgradedProtectorStats!L79 -> 7 | M22: =UpgradedProtectorStats!M79 -> 8.4 | N22: =UpgradedProtectorStats!N79 -> 0 | O22: =UpgradedProtectorStats!O79 -> 0.9 | P22: =UpgradedProtectorStats!P79 -> 200 | Q22: =UpgradedProtectorStats!Q79 -> 0 | S22: =C22/O22 -> 0 | T22: =D22/O22 -> 21.511111 | U22: =E22/O22 -> 26.888889 | V22: =F22/O22 -> 13.444444 | W22: =G22/O22 -> 16.133333 | X22: =H22/O22 -> 22.371556 | Y22: =I22/O22 -> 23.232 | Z22: =J22/O22 -> 21.511111 | AA22: =K22/O22 -> 7.7777778 | AB22: =M22/O22 -> 9.3333333
A23: =UpgradedProtectorStats!A83+10 -> 230020 | B23: Tattered Cloth Hood +10 | C23: =UpgradedProtectorStats!C83 -> 0 | D23: =UpgradedProtectorStats!D83 -> 19.36 | E23: =UpgradedProtectorStats!E83 -> 21.78 | F23: =UpgradedProtectorStats!F83 -> 29.04 | G23: =UpgradedProtectorStats!G83 -> 14.52 | H23: =UpgradedProtectorStats!D83*(1+(UpgradedProtectorStats!H83/100)) -> 19.36 | I23: =UpgradedProtectorStats!D83*(1+(UpgradedProtectorStats!I83/100)) -> 21.4896 | J23: =UpgradedProtectorStats!D83*(1+(UpgradedProtectorStats!J83/100)) -> 19.36 | K23: =UpgradedProtectorStats!K83 -> 32.2 | L23: =UpgradedProtectorStats!L83 -> 32.2 | M23: =UpgradedProtectorStats!M83 -> 12.6 | N23: =UpgradedProtectorStats!N83 -> 1.4 | O23: =UpgradedProtectorStats!O83 -> 1.1 | P23: =UpgradedProtectorStats!P83 -> 400 | Q23: =UpgradedProtectorStats!Q83 -> 0 | S23: =C23/O23 -> 0 | T23: =D23/O23 -> 17.6 | U23: =E23/O23 -> 19.8 | V23: =F23/O23 -> 26.4 | W23: =G23/O23 -> 13.2 | X23: =H23/O23 -> 17.6 | Y23: =I23/O23 -> 19.536 | Z23: =J23/O23 -> 17.6 | AA23: =K23/O23 -> 29.272727 | AB23: =M23/O23 -> 11.454545
A24: =UpgradedProtectorStats!A87+10 -> 240020 | B24: Pharis's Hat +10 | C24: =UpgradedProtectorStats!C87 -> 0 | D24: =UpgradedProtectorStats!D87 -> 16.94 | E24: =UpgradedProtectorStats!E87 -> 12.1 | F24: =UpgradedProtectorStats!F87 -> 16.94 | G24: =UpgradedProtectorStats!G87 -> 14.52 | H24: =UpgradedProtectorStats!D87*(1+(UpgradedProtectorStats!H87/100)) -> 16.94 | I24: =UpgradedProtectorStats!D87*(1+(UpgradedProtectorStats!I87/100)) -> 17.9564 | J24: =UpgradedProtectorStats!D87*(1+(UpgradedProtectorStats!J87/100)) -> 16.94 | K24: =UpgradedProtectorStats!K87 -> 7 | L24: =UpgradedProtectorStats!L87 -> 7 | M24: =UpgradedProtectorStats!M87 -> 8.4 | N24: =UpgradedProtectorStats!N87 -> 0 | O24: =UpgradedProtectorStats!O87 -> 1.2 | P24: =UpgradedProtectorStats!P87 -> 250 | Q24: =UpgradedProtectorStats!Q87 -> 0 | S24: =C24/O24 -> 0 | T24: =D24/O24 -> 14.116667 | U24: =E24/O24 -> 10.083333 | V24: =F24/O24 -> 14.116667 | W24: =G24/O24 -> 12.1 | X24: =H24/O24 -> 14.116667 | Y24: =I24/O24 -> 14.963667 | Z24: =J24/O24 -> 14.116667 | AA24: =K24/O24 -> 5.8333333 | AB24: =M24/O24 -> 7
A25: =UpgradedProtectorStats!A91+5 -> 250010 | B25: Painting Guardian Hood +5 | C25: =UpgradedProtectorStats!C91 -> 0 | D25: =UpgradedProtectorStats!D91 -> 4.65 | E25: =UpgradedProtectorStats!E91 -> 48.05 | F25: =UpgradedProtectorStats!F91 -> 17.05 | G25: =UpgradedProtectorStats!G91 -> 12.4 | H25: =UpgradedProtectorStats!D91*(1+(UpgradedProtectorStats!H91/100)) -> 4.65 | I25: =UpgradedProtectorStats!D91*(1+(UpgradedProtectorStats!I91/100)) -> 5.58 | J25: =UpgradedProtectorStats!D91*(1+(UpgradedProtectorStats!J91/100)) -> 4.65 | K25: =UpgradedProtectorStats!K91 -> 38.1 | L25: =UpgradedProtectorStats!L91 -> 38.1 | M25: =UpgradedProtectorStats!M91 -> 15.24 | N25: =UpgradedProtectorStats!N91 -> 7.62 | O25: =UpgradedProtectorStats!O91 -> 0.6 | P25: =UpgradedProtectorStats!P91 -> 150 | Q25: =UpgradedProtectorStats!Q91 -> 0 | S25: =C25/O25 -> 0 | T25: =D25/O25 -> 7.75 | U25: =E25/O25 -> 80.083333 | V25: =F25/O25 -> 28.416667 | W25: =G25/O25 -> 20.666667 | X25: =H25/O25 -> 7.75 | Y25: =I25/O25 -> 9.3 | Z25: =J25/O25 -> 7.75 | AA25: =K25/O25 -> 63.5 | AB25: =M25/O25 -> 25.4
A26: =UpgradedProtectorStats!A95 -> 270000 | B26: Ornstein's Helm | C26: =UpgradedProtectorStats!C95 -> 9 | D26: =UpgradedProtectorStats!D95 -> 32 | E26: =UpgradedProtectorStats!E95 -> 16 | F26: =UpgradedProtectorStats!F95 -> 22 | G26: =UpgradedProtectorStats!G95 -> 18 | H26: =UpgradedProtectorStats!D95*(1+(UpgradedProtectorStats!H95/100)) -> 36.16 | I26: =UpgradedProtectorStats!D95*(1+(UpgradedProtectorStats!I95/100)) -> 30.4 | J26: =UpgradedProtectorStats!D95*(1+(UpgradedProtectorStats!J95/100)) -> 32 | K26: =UpgradedProtectorStats!K95 -> 8 | L26: =UpgradedProtectorStats!L95 -> 8 | M26: =UpgradedProtectorStats!M95 -> 18 | N26: =UpgradedProtectorStats!N95 -> 8 | O26: =UpgradedProtectorStats!O95 -> 5.5 | P26: =UpgradedProtectorStats!P95 -> 700 | Q26: =UpgradedProtectorStats!Q95 -> -1 | S26: =C26/O26 -> 1.6363636 | T26: =D26/O26 -> 5.8181818 | U26: =E26/O26 -> 2.9090909 | V26: =F26/O26 -> 4 | W26: =G26/O26 -> 3.2727273 | X26: =H26/O26 -> 6.5745455 | Y26: =I26/O26 -> 5.5272727 | Z26: =J26/O26 -> 5.8181818 | AA26: =K26/O26 -> 1.4545455 | AB26: =M26/O26 -> 3.2727273
A27: =UpgradedProtectorStats!A99+5 -> 280010 | B27: Eastern Helm +5 | C27: =UpgradedProtectorStats!C99 -> 8 | D27: =UpgradedProtectorStats!D99 -> 26.35 | E27: =UpgradedProtectorStats!E99 -> 9.3 | F27: =UpgradedProtectorStats!F99 -> 18.6 | G27: =UpgradedProtectorStats!G99 -> 10.85 | H27: =UpgradedProtectorStats!D99*(1+(UpgradedProtectorStats!H99/100)) -> 32.674 | I27: =UpgradedProtectorStats!D99*(1+(UpgradedProtectorStats!I99/100)) -> 25.0325 | J27: =UpgradedProtectorStats!D99*(1+(UpgradedProtectorStats!J99/100)) -> 25.5595 | K27: =UpgradedProtectorStats!K99 -> 13.97 | L27: =UpgradedProtectorStats!L99 -> 13.97 | M27: =UpgradedProtectorStats!M99 -> 19.05 | N27: =UpgradedProtectorStats!N99 -> 0 | O27: =UpgradedProtectorStats!O99 -> 4.7 | P27: =UpgradedProtectorStats!P99 -> 450 | Q27: =UpgradedProtectorStats!Q99 -> 0 | S27: =C27/O27 -> 1.7021277 | T27: =D27/O27 -> 5.606383 | U27: =E27/O27 -> 1.9787234 | V27: =F27/O27 -> 3.9574468 | W27: =G27/O27 -> 2.3085106 | X27: =H27/O27 -> 6.9519149 | Y27: =I27/O27 -> 5.3260638 | Z27: =J27/O27 -> 5.4381915 | AA27: =K27/O27 -> 2.9723404 | AB27: =M27/O27 -> 4.0531915
A28: =UpgradedProtectorStats!A103+5 -> 290010 | B28: Xanthous Crown +5 | C28: =UpgradedProtectorStats!C103 -> 0 | D28: =UpgradedProtectorStats!D103 -> 27.9 | E28: =UpgradedProtectorStats!E103 -> 23.25 | F28: =UpgradedProtectorStats!F103 -> 4.65 | G28: =UpgradedProtectorStats!G103 -> 12.4 | H28: =UpgradedProtectorStats!D103*(1+(UpgradedProtectorStats!H103/100)) -> 27.9 | I28: =UpgradedProtectorStats!D103*(1+(UpgradedProtectorStats!I103/100)) -> 42.966 | J28: =UpgradedProtectorStats!D103*(1+(UpgradedProtectorStats!J103/100)) -> 23.715 | K28: =UpgradedProtectorStats!K103 -> 13.97 | L28: =UpgradedProtectorStats!L103 -> 13.97 | M28: =UpgradedProtectorStats!M103 -> 10.16 | N28: =UpgradedProtectorStats!N103 -> 44.45 | O28: =UpgradedProtectorStats!O103 -> 5 | P28: =UpgradedProtectorStats!P103 -> 400 | Q28: =UpgradedProtectorStats!Q103 -> 0 | S28: =C28/O28 -> 0 | T28: =D28/O28 -> 5.58 | U28: =E28/O28 -> 4.65 | V28: =F28/O28 -> 0.93 | W28: =G28/O28 -> 2.48 | X28: =H28/O28 -> 5.58 | Y28: =I28/O28 -> 8.5932 | Z28: =J28/O28 -> 4.743 | AA28: =K28/O28 -> 2.794 | AB28: =M28/O28 -> 2.032
A29: =UpgradedProtectorStats!A107+10 -> 300020 | B29: Thief Mask +10 | C29: =UpgradedProtectorStats!C107 -> 0 | D29: =UpgradedProtectorStats!D107 -> 21.78 | E29: =UpgradedProtectorStats!E107 -> 19.36 | F29: =UpgradedProtectorStats!F107 -> 12.1 | G29: =UpgradedProtectorStats!G107 -> 14.52 | H29: =UpgradedProtectorStats!D107*(1+(UpgradedProtectorStats!H107/100)) -> 21.78 | I29: =UpgradedProtectorStats!D107*(1+(UpgradedProtectorStats!I107/100)) -> 23.3046 | J29: =UpgradedProtectorStats!D107*(1+(UpgradedProtectorStats!J107/100)) -> 21.78 | K29: =UpgradedProtectorStats!K107 -> 16.8 | L29: =UpgradedProtectorStats!L107 -> 16.8 | M29: =UpgradedProtectorStats!M107 -> 12.6 | N29: =UpgradedProtectorStats!N107 -> 0 | O29: =UpgradedProtectorStats!O107 -> 1.2 | P29: =UpgradedProtectorStats!P107 -> 250 | Q29: =UpgradedProtectorStats!Q107 -> 0 | S29: =C29/O29 -> 0 | T29: =D29/O29 -> 18.15 | U29: =E29/O29 -> 16.133333 | V29: =F29/O29 -> 10.083333 | W29: =G29/O29 -> 12.1 | X29: =H29/O29 -> 18.15 | Y29: =I29/O29 -> 19.4205 | Z29: =J29/O29 -> 18.15 | AA29: =K29/O29 -> 14 | AB29: =M29/O29 -> 10.5
A30: =UpgradedProtectorStats!A111+10 -> 310020 | B30: Priest's Hat +10 | C30: =UpgradedProtectorStats!C111 -> 0 | D30: =UpgradedProtectorStats!D111 -> 19.36 | E30: =UpgradedProtectorStats!E111 -> 21.78 | F30: =UpgradedProtectorStats!F111 -> 4.84 | G30: =UpgradedProtectorStats!G111 -> 16.94 | H30: =UpgradedProtectorStats!D111*(1+(UpgradedProtectorStats!H111/100)) -> 19.36 | I30: =UpgradedProtectorStats!D111*(1+(UpgradedProtectorStats!I111/100)) -> 22.8448 | J30: =UpgradedProtectorStats!D111*(1+(UpgradedProtectorStats!J111/100)) -> 19.36 | K30: =UpgradedProtectorStats!K111 -> 11.2 | L30: =UpgradedProtectorStats!L111 -> 11.2 | M30: =UpgradedProtectorStats!M111 -> 12.6 | N30: =UpgradedProtectorStats!N111 -> 0 | O30: =UpgradedProtectorStats!O111 -> 1.2 | P30: =UpgradedProtectorStats!P111 -> 350 | Q30: =UpgradedProtectorStats!Q111 -> 0 | S30: =C30/O30 -> 0 | T30: =D30/O30 -> 16.133333 | U30: =E30/O30 -> 18.15 | V30: =F30/O30 -> 4.0333333 | W30: =G30/O30 -> 14.116667 | X30: =H30/O30 -> 16.133333 | Y30: =I30/O30 -> 19.037333 | Z30: =J30/O30 -> 16.133333 | AA30: =K30/O30 -> 9.3333333 | AB30: =M30/O30 -> 10.5
A31: =UpgradedProtectorStats!A115+5 -> 320010 | B31: Black Knight Helm +5 | C31: =UpgradedProtectorStats!C115 -> 8 | D31: =UpgradedProtectorStats!D115 -> 32.55 | E31: =UpgradedProtectorStats!E115 -> 17.05 | F31: =UpgradedProtectorStats!F115 -> 27.9 | G31: =UpgradedProtectorStats!G115 -> 9.3 | H31: =UpgradedProtectorStats!D115*(1+(UpgradedProtectorStats!H115/100)) -> 36.7815 | I31: =UpgradedProtectorStats!D115*(1+(UpgradedProtectorStats!I115/100)) -> 30.9225 | J31: =UpgradedProtectorStats!D115*(1+(UpgradedProtectorStats!J115/100)) -> 31.899 | K31: =UpgradedProtectorStats!K115 -> 7.62 | L31: =UpgradedProtectorStats!L115 -> 7.62 | M31: =UpgradedProtectorStats!M115 -> 15.24 | N31: =UpgradedProtectorStats!N115 -> 0 | O31: =UpgradedProtectorStats!O115 -> 5 | P31: =UpgradedProtectorStats!P115 -> 550 | Q31: =UpgradedProtectorStats!Q115 -> -1 | S31: =C31/O31 -> 1.6 | T31: =D31/O31 -> 6.51 | U31: =E31/O31 -> 3.41 | V31: =F31/O31 -> 5.58 | W31: =G31/O31 -> 1.86 | X31: =H31/O31 -> 7.3563 | Y31: =I31/O31 -> 6.1845 | Z31: =J31/O31 -> 6.3798 | AA31: =K31/O31 -> 1.524 | AB31: =M31/O31 -> 3.048
A32: =UpgradedProtectorStats!A119 -> 330000 | B32: Crown of Dusk | C32: =UpgradedProtectorStats!C119 -> 0 | D32: =UpgradedProtectorStats!D119 -> 5 | E32: =UpgradedProtectorStats!E119 -> 11 | F32: =UpgradedProtectorStats!F119 -> 2 | G32: =UpgradedProtectorStats!G119 -> 6 | H32: =UpgradedProtectorStats!D119*(1+(UpgradedProtectorStats!H119/100)) -> 5 | I32: =UpgradedProtectorStats!D119*(1+(UpgradedProtectorStats!I119/100)) -> 5 | J32: =UpgradedProtectorStats!D119*(1+(UpgradedProtectorStats!J119/100)) -> 5 | K32: =UpgradedProtectorStats!K119 -> 5 | L32: =UpgradedProtectorStats!L119 -> 5 | M32: =UpgradedProtectorStats!M119 -> 5 | N32: =UpgradedProtectorStats!N119 -> 20 | O32: =UpgradedProtectorStats!O119 -> 0.4 | P32: =UpgradedProtectorStats!P119 -> 150 | Q32: =UpgradedProtectorStats!Q119 -> 0 | S32: =C32/O32 -> 0 | T32: =D32/O32 -> 12.5 | U32: =E32/O32 -> 27.5 | V32: =F32/O32 -> 5 | W32: =G32/O32 -> 15 | X32: =H32/O32 -> 12.5 | Y32: =I32/O32 -> 12.5 | Z32: =J32/O32 -> 12.5 | AA32: =K32/O32 -> 12.5 | AB32: =M32/O32 -> 12.5
A33: =UpgradedProtectorStats!A123+5 -> 340010 | B33: Witch Hat +5 | C33: =UpgradedProtectorStats!C123 -> 0 | D33: =UpgradedProtectorStats!D123 -> 13.95 | E33: =UpgradedProtectorStats!E123 -> 18.6 | F33: =UpgradedProtectorStats!F123 -> 9.3 | G33: =UpgradedProtectorStats!G123 -> 10.85 | H33: =UpgradedProtectorStats!D123*(1+(UpgradedProtectorStats!H123/100)) -> 13.95 | I33: =UpgradedProtectorStats!D123*(1+(UpgradedProtectorStats!I123/100)) -> 15.4845 | J33: =UpgradedProtectorStats!D123*(1+(UpgradedProtectorStats!J123/100)) -> 13.95 | K33: =UpgradedProtectorStats!K123 -> 12.7 | L33: =UpgradedProtectorStats!L123 -> 12.7 | M33: =UpgradedProtectorStats!M123 -> 12.7 | N33: =UpgradedProtectorStats!N123 -> 13.97 | O33: =UpgradedProtectorStats!O123 -> 1.1 | P33: =UpgradedProtectorStats!P123 -> 250 | Q33: =UpgradedProtectorStats!Q123 -> 0 | S33: =C33/O33 -> 0 | T33: =D33/O33 -> 12.681818 | U33: =E33/O33 -> 16.909091 | V33: =F33/O33 -> 8.4545455 | W33: =G33/O33 -> 9.8636364 | X33: =H33/O33 -> 12.681818 | Y33: =I33/O33 -> 14.076818 | Z33: =J33/O33 -> 12.681818 | AA33: =K33/O33 -> 11.545455 | AB33: =M33/O33 -> 11.545455
A34: =UpgradedProtectorStats!A127+10 -> 350020 | B34: Elite Knight Helm +10 | C34: =UpgradedProtectorStats!C127 -> 8 | D34: =UpgradedProtectorStats!D127 -> 36.3 | E34: =UpgradedProtectorStats!E127 -> 16.94 | F34: =UpgradedProtectorStats!F127 -> 19.36 | G34: =UpgradedProtectorStats!G127 -> 14.52 | H34: =UpgradedProtectorStats!D127*(1+(UpgradedProtectorStats!H127/100)) -> 42.108 | I34: =UpgradedProtectorStats!D127*(1+(UpgradedProtectorStats!I127/100)) -> 35.211 | J34: =UpgradedProtectorStats!D127*(1+(UpgradedProtectorStats!J127/100)) -> 36.3 | K34: =UpgradedProtectorStats!K127 -> 8.4 | L34: =UpgradedProtectorStats!L127 -> 8.4 | M34: =UpgradedProtectorStats!M127 -> 12.6 | N34: =UpgradedProtectorStats!N127 -> 0 | O34: =UpgradedProtectorStats!O127 -> 4.5 | P34: =UpgradedProtectorStats!P127 -> 450 | Q34: =UpgradedProtectorStats!Q127 -> 0 | S34: =C34/O34 -> 1.7777778 | T34: =D34/O34 -> 8.0666667 | U34: =E34/O34 -> 3.7644444 | V34: =F34/O34 -> 4.3022222 | W34: =G34/O34 -> 3.2266667 | X34: =H34/O34 -> 9.3573333 | Y34: =I34/O34 -> 7.8246667 | Z34: =J34/O34 -> 8.0666667 | AA34: =K34/O34 -> 1.8666667 | AB34: =M34/O34 -> 2.8
A35: =UpgradedProtectorStats!A131+10 -> 360020 | B35: Wanderer Hood +10 | C35: =UpgradedProtectorStats!C131 -> 0 | D35: =UpgradedProtectorStats!D131 -> 13.95 | E35: =UpgradedProtectorStats!E131 -> 12.4 | F35: =UpgradedProtectorStats!F131 -> 15.5 | G35: =UpgradedProtectorStats!G131 -> 13.95 | H35: =UpgradedProtectorStats!D131*(1+(UpgradedProtectorStats!H131/100)) -> 14.9265 | I35: =UpgradedProtectorStats!D131*(1+(UpgradedProtectorStats!I131/100)) -> 14.9265 | J35: =UpgradedProtectorStats!D131*(1+(UpgradedProtectorStats!J131/100)) -> 13.95 | K35: =UpgradedProtectorStats!K131 -> 10.16 | L35: =UpgradedProtectorStats!L131 -> 10.16 | M35: =UpgradedProtectorStats!M131 -> 10.16 | N35: =UpgradedProtectorStats!N131 -> 0 | O35: =UpgradedProtectorStats!O131 -> 1.4 | P35: =UpgradedProtectorStats!P131 -> 400 | Q35: =UpgradedProtectorStats!Q131 -> 0 | S35: =C35/O35 -> 0 | T35: =D35/O35 -> 9.9642857 | U35: =E35/O35 -> 8.8571429 | V35: =F35/O35 -> 11.071429 | W35: =G35/O35 -> 9.9642857 | X35: =H35/O35 -> 10.661786 | Y35: =I35/O35 -> 10.661786 | Z35: =J35/O35 -> 9.9642857 | AA35: =K35/O35 -> 7.2571429 | AB35: =M35/O35 -> 7.2571429
A36: =UpgradedProtectorStats!A135+10 -> 370020 | B36: Mage Smith Hat +10 | C36: =UpgradedProtectorStats!C135 -> 0 | D36: =UpgradedProtectorStats!D135 -> 12.4 | E36: =UpgradedProtectorStats!E135 -> 15.5 | F36: =UpgradedProtectorStats!F135 -> 7.75 | G36: =UpgradedProtectorStats!G135 -> 9.3 | H36: =UpgradedProtectorStats!D135*(1+(UpgradedProtectorStats!H135/100)) -> 12.896 | I36: =UpgradedProtectorStats!D135*(1+(UpgradedProtectorStats!I135/100)) -> 13.392 | J36: =UpgradedProtectorStats!D135*(1+(UpgradedProtectorStats!J135/100)) -> 12.4 | K36: =UpgradedProtectorStats!K135 -> 6.35 | L36: =UpgradedProtectorStats!L135 -> 6.35 | M36: =UpgradedProtectorStats!M135 -> 7.62 | N36: =UpgradedProtectorStats!N135 -> 0 | O36: =UpgradedProtectorStats!O135 -> 0.9 | P36: =UpgradedProtectorStats!P135 -> 200 | Q36: =UpgradedProtectorStats!Q135 -> 0 | S36: =C36/O36 -> 0 | T36: =D36/O36 -> 13.777778 | U36: =E36/O36 -> 17.222222 | V36: =F36/O36 -> 8.6111111 | W36: =G36/O36 -> 10.333333 | X36: =H36/O36 -> 14.328889 | Y36: =I36/O36 -> 14.88 | Z36: =J36/O36 -> 13.777778 | AA36: =K36/O36 -> 7.0555556 | AB36: =M36/O36 -> 8.4666667
A37: =UpgradedProtectorStats!A139+5 -> 380010 | B37: Big Hat +5 | C37: =UpgradedProtectorStats!C139 -> 0 | D37: =UpgradedProtectorStats!D139 -> 21.7 | E37: =UpgradedProtectorStats!E139 -> 66.65 | F37: =UpgradedProtectorStats!F139 -> 10.85 | G37: =UpgradedProtectorStats!G139 -> 26.35 | H37: =UpgradedProtectorStats!D139*(1+(UpgradedProtectorStats!H139/100)) -> 23.87 | I37: =UpgradedProtectorStats!D139*(1+(UpgradedProtectorStats!I139/100)) -> 23.87 | J37: =UpgradedProtectorStats!D139*(1+(UpgradedProtectorStats!J139/100)) -> 19.53 | K37: =UpgradedProtectorStats!K139 -> 16.51 | L37: =UpgradedProtectorStats!L139 -> 16.51 | M37: =UpgradedProtectorStats!M139 -> 16.51 | N37: =UpgradedProtectorStats!N139 -> 0 | O37: =UpgradedProtectorStats!O139 -> 3 | P37: =UpgradedProtectorStats!P139 -> 250 | Q37: =UpgradedProtectorStats!Q139 -> 0 | S37: =C37/O37 -> 0 | T37: =D37/O37 -> 7.2333333 | U37: =E37/O37 -> 22.216667 | V37: =F37/O37 -> 3.6166667 | W37: =G37/O37 -> 8.7833333 | X37: =H37/O37 -> 7.9566667 | Y37: =I37/O37 -> 7.9566667 | Z37: =J37/O37 -> 6.51 | AA37: =K37/O37 -> 5.5033333 | AB37: =M37/O37 -> 5.5033333
A38: =UpgradedProtectorStats!A143+10 -> 390020 | B38: Knight Helm +10 | C38: =UpgradedProtectorStats!C143 -> 8 | D38: =UpgradedProtectorStats!D143 -> 33.88 | E38: =UpgradedProtectorStats!E143 -> 14.52 | F38: =UpgradedProtectorStats!F143 -> 19.36 | G38: =UpgradedProtectorStats!G143 -> 12.1 | H38: =UpgradedProtectorStats!D143*(1+(UpgradedProtectorStats!H143/100)) -> 39.3008 | I38: =UpgradedProtectorStats!D143*(1+(UpgradedProtectorStats!I143/100)) -> 32.186 | J38: =UpgradedProtectorStats!D143*(1+(UpgradedProtectorStats!J143/100)) -> 33.2024 | K38: =UpgradedProtectorStats!K143 -> 8.4 | L38: =UpgradedProtectorStats!L143 -> 8.4 | M38: =UpgradedProtectorStats!M143 -> 12.6 | N38: =UpgradedProtectorStats!N143 -> 0 | O38: =UpgradedProtectorStats!O143 -> 4.2 | P38: =UpgradedProtectorStats!P143 -> 400 | Q38: =UpgradedProtectorStats!Q143 -> 0 | S38: =C38/O38 -> 1.9047619 | T38: =D38/O38 -> 8.0666667 | U38: =E38/O38 -> 3.4571429 | V38: =F38/O38 -> 4.6095238 | W38: =G38/O38 -> 2.8809524 | X38: =H38/O38 -> 9.3573333 | Y38: =I38/O38 -> 7.6633333 | Z38: =J38/O38 -> 7.9053333 | AA38: =K38/O38 -> 2 | AB38: =M38/O38 -> 3
A39: =UpgradedProtectorStats!A147+10 -> 400020 | B39: Dingy Hood +10 | C39: =UpgradedProtectorStats!C147 -> 0 | D39: =UpgradedProtectorStats!D147 -> 14.52 | E39: =UpgradedProtectorStats!E147 -> 19.36 | F39: =UpgradedProtectorStats!F147 -> 12.1 | G39: =UpgradedProtectorStats!G147 -> 14.52 | H39: =UpgradedProtectorStats!D147*(1+(UpgradedProtectorStats!H147/100)) -> 14.52 | I39: =UpgradedProtectorStats!D147*(1+(UpgradedProtectorStats!I147/100)) -> 18.15 | J39: =UpgradedProtectorStats!D147*(1+(UpgradedProtectorStats!J147/100)) -> 14.52 | K39: =UpgradedProtectorStats!K147 -> 9.8 | L39: =UpgradedProtectorStats!L147 -> 9.8 | M39: =UpgradedProtectorStats!M147 -> 12.6 | N39: =UpgradedProtectorStats!N147 -> 12.6 | O39: =UpgradedProtectorStats!O147 -> 0.8 | P39: =UpgradedProtectorStats!P147 -> 150 | Q39: =UpgradedProtectorStats!Q147 -> 0 | S39: =C39/O39 -> 0 | T39: =D39/O39 -> 18.15 | U39: =E39/O39 -> 24.2 | V39: =F39/O39 -> 15.125 | W39: =G39/O39 -> 18.15 | X39: =H39/O39 -> 18.15 | Y39: =I39/O39 -> 22.6875 | Z39: =J39/O39 -> 18.15 | AA39: =K39/O39 -> 12.25 | AB39: =M39/O39 -> 15.75
A40: =UpgradedProtectorStats!A151+10 -> 410020 | B40: Maiden Hood +10 | C40: =UpgradedProtectorStats!C151 -> 0 | D40: =UpgradedProtectorStats!D151 -> 16.94 | E40: =UpgradedProtectorStats!E151 -> 19.36 | F40: =UpgradedProtectorStats!F151 -> 12.1 | G40: =UpgradedProtectorStats!G151 -> 14.52 | H40: =UpgradedProtectorStats!D151*(1+(UpgradedProtectorStats!H151/100)) -> 16.94 | I40: =UpgradedProtectorStats!D151*(1+(UpgradedProtectorStats!I151/100)) -> 19.8198 | J40: =UpgradedProtectorStats!D151*(1+(UpgradedProtectorStats!J151/100)) -> 16.94 | K40: =UpgradedProtectorStats!K151 -> 9.8 | L40: =UpgradedProtectorStats!L151 -> 9.8 | M40: =UpgradedProtectorStats!M151 -> 12.6 | N40: =UpgradedProtectorStats!N151 -> 4.2 | O40: =UpgradedProtectorStats!O151 -> 0.8 | P40: =UpgradedProtectorStats!P151 -> 150 | Q40: =UpgradedProtectorStats!Q151 -> 0 | S40: =C40/O40 -> 0 | T40: =D40/O40 -> 21.175 | U40: =E40/O40 -> 24.2 | V40: =F40/O40 -> 15.125 | W40: =G40/O40 -> 18.15 | X40: =H40/O40 -> 21.175 | Y40: =I40/O40 -> 24.77475 | Z40: =J40/O40 -> 21.175 | AA40: =K40/O40 -> 12.25 | AB40: =M40/O40 -> 15.75
...

Sheet Armor
A1: ID | B1: Name | C1: Poise | D1: physDef | E1: magDef | F1: fireDef | G1: litngDef | H1: slashDef | I1: blowDef | J1: thrustDef | K1: poisonRes | L1: toxicRes | M1: bleedRes | N1: curseRes | O1: Weight | P1: Durability | Q1: RegPenalty | S1: Poise/Weight | T1: physDef/Weight | U1: magDef/Weight | V1: fireDef/Weight | W1: lingDef/Weight | X1: slash/Weight | Y1: blow/Weight | Z1: thrust/Weight | AA1: poison/Weight | AB1: bleed/Weight
A2: =UpgradedProtectorStats!A3+5 -> 11010 | B2: Catarina Armor +5 | C2: =UpgradedProtectorStats!C3 -> 21 | D2: =UpgradedProtectorStats!D3 -> 88.35 | E2: =UpgradedProtectorStats!E3 -> 48.05 | F2: =UpgradedProtectorStats!F3 -> 57.35 | G2: =UpgradedProtectorStats!G3 -> 29.45 | H2: =UpgradedProtectorStats!D3*(1+(UpgradedProtectorStats!H3/100)) -> 101.6025 | I2: =UpgradedProtectorStats!D3*(1+(UpgradedProtectorStats!I3/100)) -> 87.4665 | J2: =UpgradedProtectorStats!D3*(1+(UpgradedProtectorStats!J3/100)) -> 88.35 | K2: =UpgradedProtectorStats!K3 -> 30.48 | L2: =UpgradedProtectorStats!L3 -> 30.48 | M2: =UpgradedProtectorStats!M3 -> 43.18 | N2: =UpgradedProtectorStats!N3 -> 0 | O2: =UpgradedProtectorStats!O3 -> 11.7 | P2: =UpgradedProtectorStats!P3 -> 400 | Q2: =UpgradedProtectorStats!Q3 -> -1 | S2: =C2/O2 -> 1.7948718 | T2: =D2/O2 -> 7.5512821 | U2: =E2/O2 -> 4.1068376 | V2: =F2/O2 -> 4.9017094 | W2: =G2/O2 -> 2.517094 | X2: =H2/O2 -> 8.6839744 | Y2: =I2/O2 -> 7.4757692 | Z2: =J2/O2 -> 7.5512821 | AA2: =K2/O2 -> 2.6051282 | AB2: =M2/O2 -> 3.6905983
A3: =UpgradedProtectorStats!A7+5 -> 21010 | B3: Paladin Armor +5 | C3: =UpgradedProtectorStats!C7 -> 20 | D3: =UpgradedProtectorStats!D7 -> 91.45 | E3: =UpgradedProtectorStats!E7 -> 48.05 | F3: =UpgradedProtectorStats!F7 -> 57.35 | G3: =UpgradedProtectorStats!G7 -> 29.45 | H3: =UpgradedProtectorStats!D7*(1+(UpgradedProtectorStats!H7/100)) -> 105.1675 | I3: =UpgradedProtectorStats!D7*(1+(UpgradedProtectorStats!I7/100)) -> 86.8775 | J3: =UpgradedProtectorStats!D7*(1+(UpgradedProtectorStats!J7/100)) -> 91.45 | K3: =UpgradedProtectorStats!K7 -> 30.48 | L3: =UpgradedProtectorStats!L7 -> 30.48 | M3: =UpgradedProtectorStats!M7 -> 43.18 | N3: =UpgradedProtectorStats!N7 -> 72.39 | O3: =UpgradedProtectorStats!O7 -> 12.9 | P3: =UpgradedProtectorStats!P7 -> 500 | Q3: =UpgradedProtectorStats!Q7 -> -1 | S3: =C3/O3 -> 1.5503876 | T3: =D3/O3 -> 7.0891473 | U3: =E3/O3 -> 3.7248062 | V3: =F3/O3 -> 4.4457364 | W3: =G3/O3 -> 2.2829457 | X3: =H3/O3 -> 8.1525194 | Y3: =I3/O3 -> 6.7346899 | Z3: =J3/O3 -> 7.0891473 | AA3: =K3/O3 -> 2.3627907 | AB3: =M3/O3 -> 3.3472868
A4: =UpgradedProtectorStats!A11+5 -> 41010 | B4: Dark Armor +5 | C4: =UpgradedProtectorStats!C11 -> 16 | D4: =UpgradedProtectorStats!D11 -> 69.75 | E4: =UpgradedProtectorStats!E11 -> 46.5 | F4: =UpgradedProtectorStats!F11 -> 48.05 | G4: =UpgradedProtectorStats!G11 -> 41.85 | H4: =UpgradedProtectorStats!D11*(1+(UpgradedProtectorStats!H11/100)) -> 76.725 | I4: =UpgradedProtectorStats!D11*(1+(UpgradedProtectorStats!I11/100)) -> 69.75 | J4: =UpgradedProtectorStats!D11*(1+(UpgradedProtectorStats!J11/100)) -> 65.565 | K4: =UpgradedProtectorStats!K11 -> 26.67 | L4: =UpgradedProtectorStats!L11 -> 26.67 | M4: =UpgradedProtectorStats!M11 -> 38.1 | N4: =UpgradedProtectorStats!N11 -> 0 | O4: =UpgradedProtectorStats!O11 -> 9.8 | P4: =UpgradedProtectorStats!P11 -> 300 | Q4: =UpgradedProtectorStats!Q11 -> 0 | S4: =C4/O4 -> 1.6326531 | T4: =D4/O4 -> 7.1173469 | U4: =E4/O4 -> 4.744898 | V4: =F4/O4 -> 4.9030612 | W4: =G4/O4 -> 4.2704082 | X4: =H4/O4 -> 7.8290816 | Y4: =I4/O4 -> 7.1173469 | Z4: =J4/O4 -> 6.6903061 | AA4: =K4/O4 -> 2.7214286 | AB4: =M4/O4 -> 3.8877551
A5: =UpgradedProtectorStats!A15+10 -> 51020 | B5: Brigand Armor +10 | C5: =UpgradedProtectorStats!C15 -> 0 | D5: =UpgradedProtectorStats!D15 -> 55.66 | E5: =UpgradedProtectorStats!E15 -> 48.4 | F5: =UpgradedProtectorStats!F15 -> 31.46 | G5: =UpgradedProtectorStats!G15 -> 41.14 | H5: =UpgradedProtectorStats!D15*(1+(UpgradedProtectorStats!H15/100)) -> 55.66 | I5: =UpgradedProtectorStats!D15*(1+(UpgradedProtectorStats!I15/100)) -> 61.226 | J5: =UpgradedProtectorStats!D15*(1+(UpgradedProtectorStats!J15/100)) -> 50.094 | K5: =UpgradedProtectorStats!K15 -> 28 | L5: =UpgradedProtectorStats!L15 -> 28 | M5: =UpgradedProtectorStats!M15 -> 28 | N5: =UpgradedProtectorStats!N15 -> 0 | O5: =UpgradedProtectorStats!O15 -> 3.1 | P5: =UpgradedProtectorStats!P15 -> 200 | Q5: =UpgradedProtectorStats!Q15 -> 0 | S5: =C5/O5 -> 0 | T5: =D5/O5 -> 17.954839 | U5: =E5/O5 -> 15.612903 | V5: =F5/O5 -> 10.148387 | W5: =G5/O5 -> 13.270968 | X5: =H5/O5 -> 17.954839 | Y5: =I5/O5 -> 19.750323 | Z5: =J5/O5 -> 16.159355 | AA5: =K5/O5 -> 9.0322581 | AB5: =M5/O5 -> 9.0322581
A6: =UpgradedProtectorStats!A19+5 -> 61010 | B6: Shadow Garb +5 | C6: =UpgradedProtectorStats!C19 -> 0 | D6: =UpgradedProtectorStats!D19 -> 55.66 | E6: =UpgradedProtectorStats!E19 -> 29.04 | F6: =UpgradedProtectorStats!F19 -> 38.72 | G6: =UpgradedProtectorStats!G19 -> 41.14 | H6: =UpgradedProtectorStats!D19*(1+(UpgradedProtectorStats!H19/100)) -> 55.66 | I6: =UpgradedProtectorStats!D19*(1+(UpgradedProtectorStats!I19/100)) -> 61.226 | J6: =UpgradedProtectorStats!D19*(1+(UpgradedProtectorStats!J19/100)) -> 55.66 | K6: =UpgradedProtectorStats!K19 -> 65.8 | L6: =UpgradedProtectorStats!L19 -> 65.8 | M6: =UpgradedProtectorStats!M19 -> 54.6 | N6: =UpgradedProtectorStats!N19 -> 0 | O6: =UpgradedProtectorStats!O19 -> 2.3 | P6: =UpgradedProtectorStats!P19 -> 200 | Q6: =UpgradedProtectorStats!Q19 -> 0 | S6: =C6/O6 -> 0 | T6: =D6/O6 -> 24.2 | U6: =E6/O6 -> 12.626087 | V6: =F6/O6 -> 16.834783 | W6: =G6/O6 -> 17.886957 | X6: =H6/O6 -> 24.2 | Y6: =I6/O6 -> 26.62 | Z6: =J6/O6 -> 24.2 | AA6: =K6/O6 -> 28.608696 | AB6: =M6/O6 -> 23.73913
A7: =UpgradedProtectorStats!A23+5 -> 71010 | B7: Black Iron Armor +5 | C7: =UpgradedProtectorStats!C23 -> 31 | D7: =UpgradedProtectorStats!D23 -> 164.56 | E7: =UpgradedProtectorStats!E23 -> 72.6 | F7: =UpgradedProtectorStats!F23 -> 123.42 | G7: =UpgradedProtectorStats!G23 -> 50.82 | H7: =UpgradedProtectorStats!D23*(1+(UpgradedProtectorStats!H23/100)) -> 189.244 | I7: =UpgradedProtectorStats!D23*(1+(UpgradedProtectorStats!I23/100)) -> 156.332 | J7: =UpgradedProtectorStats!D23*(1+(UpgradedProtectorStats!J23/100)) -> 164.56 | K7: =UpgradedProtectorStats!K23 -> 35 | L7: =UpgradedProtectorStats!L23 -> 35 | M7: =UpgradedProtectorStats!M23 -> 60.2 | N7: =UpgradedProtectorStats!N23 -> 18.2 | O7: =UpgradedProtectorStats!O23 -> 15.6 | P7: =UpgradedProtectorStats!P23 -> 600 | Q7: =UpgradedProtectorStats!Q23 -> -2 | S7: =C7/O7 -> 1.9871795 | T7: =D7/O7 -> 10.548718 | U7: =E7/O7 -> 4.6538462 | V7: =F7/O7 -> 7.9115385 | W7: =G7/O7 -> 3.2576923 | X7: =H7/O7 -> 12.131026 | Y7: =I7/O7 -> 10.021282 | Z7: =J7/O7 -> 10.548718 | AA7: =K7/O7 -> 2.2435897 | AB7: =M7/O7 -> 3.8589744
A8: =UpgradedProtectorStats!A27 -> 81000 | B8: Smough's Armor | C8: =UpgradedProtectorStats!C27 -> 35 | D8: =UpgradedProtectorStats!D27 -> 106 | E8: =UpgradedProtectorStats!E27 -> 52 | F8: =UpgradedProtectorStats!F27 -> 66 | G8: =UpgradedProtectorStats!G27 -> 59 | H8: =UpgradedProtectorStats!D27*(1+(UpgradedProtectorStats!H27/100)) -> 121.9 | I8: =UpgradedProtectorStats!D27*(1+(UpgradedProtectorStats!I27/100)) -> 92.22 | J8: =UpgradedProtectorStats!D27*(1+(UpgradedProtectorStats!J27/100)) -> 106 | K8: =UpgradedProtectorStats!K27 -> 28 | L8: =UpgradedProtectorStats!L27 -> 28 | M8: =UpgradedProtectorStats!M27 -> 54 | N8: =UpgradedProtectorStats!N27 -> 9 | O8: =UpgradedProtectorStats!O27 -> 17.6 | P8: =UpgradedProtectorStats!P27 -> 700 | Q8: =UpgradedProtectorStats!Q27 -> -2 | S8: =C8/O8 -> 1.9886364 | T8: =D8/O8 -> 6.0227273 | U8: =E8/O8 -> 2.9545455 | V8: =F8/O8 -> 3.75 | W8: =G8/O8 -> 3.3522727 | X8: =H8/O8 -> 6.9261364 | Y8: =I8/O8 -> 5.2397727 | Z8: =J8/O8 -> 6.0227273 | AA8: =K8/O8 -> 1.5909091 | AB8: =M8/O8 -> 3.0681818
A9: =UpgradedProtectorStats!A31 -> 91000 | B9: Robe of the Channelers | C9: =UpgradedProtectorStats!C31 -> 12 | D9: =UpgradedProtectorStats!D31 -> 53 | E9: =UpgradedProtectorStats!E31 -> 45 | F9: =UpgradedProtectorStats!F31 -> 45 | G9: =UpgradedProtectorStats!G31 -> 35 | H9: =UpgradedProtectorStats!D31*(1+(UpgradedProtectorStats!H31/100)) -> 60.42 | I9: =UpgradedProtectorStats!D31*(1+(UpgradedProtectorStats!I31/100)) -> 50.88 | J9: =UpgradedProtectorStats!D31*(1+(UpgradedProtectorStats!J31/100)) -> 53 | K9: =UpgradedProtectorStats!K31 -> 33 | L9: =UpgradedProtectorStats!L31 -> 33 | M9: =UpgradedProtectorStats!M31 -> 38 | N9: =UpgradedProtectorStats!N31 -> 0 | O9: =UpgradedProtectorStats!O31 -> 10.1 | P9: =UpgradedProtectorStats!P31 -> 300 | Q9: =UpgradedProtectorStats!Q31 -> 0 | S9: =C9/O9 -> 1.1881188 | T9: =D9/O9 -> 5.2475248 | U9: =E9/O9 -> 4.4554455 | V9: =F9/O9 -> 4.4554455 | W9: =G9/O9 -> 3.4653465 | X9: =H9/O9 -> 5.9821782 | Y9: =I9/O9 -> 5.0376238 | Z9: =J9/O9 -> 5.2475248 | AA9: =K9/O9 -> 3.2673267 | AB9: =M9/O9 -> 3.7623762
A10: =UpgradedProtectorStats!A35+5 -> 101010 | B10: Embraced Armor of Favor +5 | C10: =UpgradedProtectorStats!C35 -> 20 | D10: =UpgradedProtectorStats!D35 -> 74.4 | E10: =UpgradedProtectorStats!E35 -> 35.65 | F10: =UpgradedProtectorStats!F35 -> 46.5 | G10: =UpgradedProtectorStats!G35 -> 29.45 | H10: =UpgradedProtectorStats!D35*(1+(UpgradedProtectorStats!H35/100)) -> 86.304 | I10: =UpgradedProtectorStats!D35*(1+(UpgradedProtectorStats!I35/100)) -> 70.68 | J10: =UpgradedProtectorStats!D35*(1+(UpgradedProtectorStats!J35/100)) -> 74.4 | K10: =UpgradedProtectorStats!K35 -> 27.94 | L10: =UpgradedProtectorStats!L35 -> 27.94 | M10: =UpgradedProtectorStats!M35 -> 35.56 | N10: =UpgradedProtectorStats!N35 -> 27.94 | O10: =UpgradedProtectorStats!O35 -> 11.7 | P10: =UpgradedProtectorStats!P35 -> 500 | Q10: =UpgradedProtectorStats!Q35 -> 0 | S10: =C10/O10 -> 1.7094017 | T10: =D10/O10 -> 6.3589744 | U10: =E10/O10 -> 3.0470085 | V10: =F10/O10 -> 3.974359 | W10: =G10/O10 -> 2.517094 | X10: =H10/O10 -> 7.3764103 | Y10: =I10/O10 -> 6.0410256 | Z10: =J10/O10 -> 6.3589744 | AA10: =K10/O10 -> 2.3880342 | AB10: =M10/O10 -> 3.0393162
A11: =UpgradedProtectorStats!A39 -> 111000 | B11: Armor of the Glorious | C11: =UpgradedProtectorStats!C39 -> 20 | D11: =UpgradedProtectorStats!D39 -> 47 | E11: =UpgradedProtectorStats!E39 -> 31 | F11: =UpgradedProtectorStats!F39 -> 34 | G11: =UpgradedProtectorStats!G39 -> 25 | H11: =UpgradedProtectorStats!D39*(1+(UpgradedProtectorStats!H39/100)) -> 54.05 | I11: =UpgradedProtectorStats!D39*(1+(UpgradedProtectorStats!I39/100)) -> 44.65 | J11: =UpgradedProtectorStats!D39*(1+(UpgradedProtectorStats!J39/100)) -> 47 | K11: =UpgradedProtectorStats!K39 -> 19 | L11: =UpgradedProtectorStats!L39 -> 19 | M11: =UpgradedProtectorStats!M39 -> 28 | N11: =UpgradedProtectorStats!N39 -> 24 | O11: =UpgradedProtectorStats!O39 -> 13.3 | P11: =UpgradedProtectorStats!P39 -> 500 | Q11: =UpgradedProtectorStats!Q39 -> -1 | S11: =C11/O11 -> 1.5037594 | T11: =D11/O11 -> 3.5338346 | U11: =E11/O11 -> 2.3308271 | V11: =F11/O11 -> 2.556391 | W11: =G11/O11 -> 1.8796992 | X11: =H11/O11 -> 4.0639098 | Y11: =I11/O11 -> 3.3571429 | Z11: =J11/O11 -> 3.5338346 | AA11: =K11/O11 -> 1.4285714 | AB11: =M11/O11 -> 2.1052632
A12: =UpgradedProtectorStats!A43 -> 121000 | B12: Stone Armor | C12: =UpgradedProtectorStats!C43 -> 39 | D12: =UpgradedProtectorStats!D43 -> 91 | E12: =UpgradedProtectorStats!E43 -> 45 | F12: =UpgradedProtectorStats!F43 -> 54 | G12: =UpgradedProtectorStats!G43 -> 54 | H12: =UpgradedProtectorStats!D43*(1+(UpgradedProtectorStats!H43/100)) -> 104.65 | I12: =UpgradedProtectorStats!D43*(1+(UpgradedProtectorStats!I43/100)) -> 85.54 | J12: =UpgradedProtectorStats!D43*(1+(UpgradedProtectorStats!J43/100)) -> 91 | K12: =UpgradedProtectorStats!K43 -> 16 | L12: =UpgradedProtectorStats!L43 -> 16 | M12: =UpgradedProtectorStats!M43 -> 45 | N12: =UpgradedProtectorStats!N43 -> 0 | O12: =UpgradedProtectorStats!O43 -> 17.6 | P12: =UpgradedProtectorStats!P43 -> 800 | Q12: =UpgradedProtectorStats!Q43 -> -2 | S12: =C12/O12 -> 2.2159091 | T12: =D12/O12 -> 5.1704545 | U12: =E12/O12 -> 2.5568182 | V12: =F12/O12 -> 3.0681818 | W12: =G12/O12 -> 3.0681818 | X12: =H12/O12 -> 5.9460227 | Y12: =I12/O12 -> 4.8602273 | Z12: =J12/O12 -> 5.1704545 | AA12: =K12/O12 -> 0.90909091 | AB12: =M12/O12 -> 2.5568182
